<?xml version="1.0" ?>
<sdf version="1.11">
    <model name='car' canonical_link='chassis'>
        <!-- <pose relative_to='world'>0 0 0 0 0 0</pose>   the pose is relative to the world by default -->

        <!--chassis-->
        <link name='chassis'>
            <pose relative_to='__model__'>0 0 0.1 0 0 0</pose>
            <inertial> <!--inertial properties of the link mass, inertia matix-->
                <mass>1.14395</mass>
                <inertia>
                    <ixx>0.095329</ixx>
                    <ixy>0</ixy>
                    <ixz>0</ixz>
                    <iyy>0.381317</iyy>
                    <iyz>0</iyz>
                    <izz>0.476646</izz>
                </inertia>
            </inertial>
            <visual name='visual'>
                <geometry>
                    <box>
                        <size>0.2 0.1 0.02</size>
                    </box>
                </geometry>
                <!--Color of the link-->
                <material>
                    <ambient>0.0 0.0 1.0 1</ambient>
                    <diffuse>0.0 0.0 1.0 1</diffuse>
                    <specular>0.0 0.0 1.0 1</specular>
                </material>
            </visual>
            <collision name='collision'>
                <geometry>
                    <box>
                        <size>0.2 0.1 0.02</size>
                    </box>
                </geometry>
            </collision>
        </link>

        <!--Left wheel-->
        <link name='left_wheel'>
            <pose relative_to="chassis">-0.05 0.06 0 -1.5707 0 0</pose> <!--angles are in radian-->
            <inertial>
                <mass>1</mass>
                <inertia>
                    <ixx>0.043333</ixx>
                    <ixy>0</ixy>
                    <ixz>0</ixz>
                    <iyy>0.043333</iyy>
                    <iyz>0</iyz>
                    <izz>0.08</izz>
                </inertia>
            </inertial>
            <visual name='visual'>
                <geometry>
                    <cylinder>
                        <radius>0.04</radius>
                        <length>0.02</length>
                    </cylinder>
                </geometry>
                <material>
                    <ambient>1.0 0.0 0.0 1</ambient>
                    <diffuse>1.0 0.0 0.0 1</diffuse>
                    <specular>1.0 0.0 0.0 1</specular>
                </material>
            </visual>
            <collision name='collision'>
                <geometry>
                    <cylinder>
                        <radius>0.04</radius>
                        <length>0.02</length>
                    </cylinder>
                </geometry>
            </collision>
        </link>

        <!--The same as left wheel but with different position-->
        <link name='right_wheel'>
            <pose relative_to="chassis">-0.05 -0.06 0 -1.5707 0 0</pose> <!--angles are in radian-->
            <inertial>
                <mass>1</mass>
                <inertia>
                    <ixx>0.043333</ixx>
                    <ixy>0</ixy>
                    <ixz>0</ixz>
                    <iyy>0.043333</iyy>
                    <iyz>0</iyz>
                    <izz>0.08</izz>
                </inertia>
            </inertial>
            <visual name='visual'>
                <geometry>
                    <cylinder>
                        <radius>0.04</radius>
                        <length>0.02</length>
                    </cylinder>
                </geometry>
                <material>
                    <ambient>1.0 0.0 0.0 1</ambient>
                    <diffuse>1.0 0.0 0.0 1</diffuse>
                    <specular>1.0 0.0 0.0 1</specular>
                </material>
            </visual>
            <collision name='collision'>
                <geometry>
                    <cylinder>
                        <radius>0.04</radius>
                        <length>0.02</length>
                    </cylinder>
                </geometry>
            </collision>
        </link>

        <!--arbitrary frame-->
        <frame name="caster_frame" attached_to='chassis'>
            <pose relative_to='chassis'>0.08 0 -0.02 0 0 0</pose>
        </frame>

        <!--caster wheel-->
        <link name='caster'>
            <!-- <pose>0.8 0 -0.2 0 0 0</pose> -->
            <pose relative_to='caster_frame'/>
            <inertial>
                <mass>1</mass>
                <inertia>
                    <ixx>0.016</ixx>
                    <ixy>0</ixy>
                    <ixz>0</ixz>
                    <iyy>0.016</iyy>
                    <iyz>0</iyz>
                    <izz>0.016</izz>
                </inertia>
            </inertial>
            <visual name='visual'>
                <geometry>
                    <sphere>
                        <radius>0.02</radius>
                    </sphere>
                </geometry>
                <material>
                    <ambient>0.0 1 0.0 1</ambient>
                    <diffuse>0.0 1 0.0 1</diffuse>
                    <specular>0.0 1 0.0 1</specular>
                </material>
            </visual>
            <collision name='collision'>
                <geometry>
                    <sphere>
                        <radius>0.02</radius>
                    </sphere>
                </geometry>
            </collision>
        </link>

        <!--left wheel joint-->
        <joint name='left_wheel_joint' type='revolute'>
            <pose relative_to='left_wheel'/>
            <parent>chassis</parent>
            <child>left_wheel</child>
            <axis>
                <xyz expressed_in='__model__'>0 1 0</xyz> <!--can be descired to any frame or even arbitrary frames-->
                <limit>
                    <lower>-1.79769e+308</lower>    <!--negative infinity-->
                    <upper>1.79769e+308</upper>     <!--positive infinity-->
                </limit>
            </axis>
        </joint>

        <!--right wheel joint-->
        <joint name='right_wheel_joint' type='revolute'>
            <pose relative_to='right_wheel'/>
            <parent>chassis</parent>
            <child>right_wheel</child>
            <axis>
                <xyz expressed_in='__model__'>0 1 0</xyz>
                <limit>
                    <lower>-1.79769e+308</lower>    <!--negative infinity-->
                    <upper>1.79769e+308</upper>     <!--positive infinity-->
                </limit>
            </axis>
        </joint>

        <!--caster wheel joint--> <!--pose defult value is the child-->
        <joint name='caster_joint' type='ball'>
            <parent>chassis</parent>
            <child>caster</child>
        </joint>

        <plugin filename="gz-sim-diff-drive-system" name="gz::sim::systems::DiffDrive">
            <left_joint>left_wheel_joint</left_joint>
            <right_joint>right_wheel_joint</right_joint>
            <wheel_separation>1.2</wheel_separation>
            <wheel_radius>0.4</wheel_radius>
            <odom_publish_frequency>1</odom_publish_frequency>
            <!-- <topic>cmd_vel</topic> -->
        </plugin>   

        <plugin filename="gz-sim-sensors-system" name="gz::sim::systems::Sensors">
            <render_engine>ogre2</render_engine>
        </plugin>

        <link name="rgbd_frame">
            <pose relative_to="sensor">0.02 0 0 0 0 0</pose>
        </link>

        <link name="sensor">
            <pose relative_to='chassis'>0.08 0 0.02 0 0 0</pose>
            <inertial auto="true">
                <density>100</density>
            </inertial>
            <collision name="collisional">
                <geometry>
                    <box>
                        <size>0.02 0.02 0.02</size>
                    </box>
                </geometry>
            </collision>
            <visual name="visual1">
                <geometry>
                    <box>
                        <size>0.02 0.02 0.02</size>
                    </box>
                </geometry>
                <material>
                    <ambient>0.0 1.0 1.0 1</ambient>
                    <diffuse>0.0 1.0 1.0 1</diffuse>
                    <specular>0.0 1.0 1.0 1</specular>
                </material>
            </visual>

            <sensor name="rgbd" type="rgbd_camera">   
                <camera>
                    <optical_frame_id>car/rgbd_frame</optical_frame_id>
                    <horizontal_fov>1.047</horizontal_fov>
                    <image>
                    <width>320</width>
                    <height>240</height>
                    </image>
                    <clip>
                    <near>0.1</near>
                    <far>100</far>
                    </clip>
                </camera>
                <always_on>1</always_on>
                <update_rate>30</update_rate>
                <visualize>true</visualize>
                <topic>model/car/sensor/rgbd</topic>
                <enable_metrics>true</enable_metrics>
            </sensor>

            <sensor name='lidar' type='gpu_lidar'>"
                <gz_frame_id>car/sensor</gz_frame_id>
                <pose relative_to="sensor">0 0 0.02 0 0 0</pose>
                <topic>model/car/sensor/lidar</topic>
                <update_rate>10</update_rate>
                <ray>
                    <scan>
                        <horizontal>
                            <samples>360</samples>
                            <resolution>1</resolution>
                            <min_angle>0.0</min_angle>
                            <max_angle>6.28</max_angle>
                        </horizontal>
                    </scan>
                    <range>
                        <min>0.12</min>
                        <max>3.5</max>
                        <resolution>0.015</resolution>
                    </range>
                </ray>
                <always_on>1</always_on>
                <visualize>true</visualize>
            </sensor>
        </link>

        <joint name="sensor_joint" type="fixed">
            <parent>chassis</parent>
            <child>sensor</child>
        </joint>

        <joint name="rgbd_joint" type="fixed">
            <parent>sensor</parent>
            <child>rgbd_frame</child>
        </joint>

    </model>
</sdf>